<sdf version='1.6'>
  <model name='pioneer3at'>
    <link name='base_link'>
      <pose frame=''>0 0 0 0 -0 0</pose>
      <inertial>
        <pose frame=''>0.008808 -0.091353 0.179477 0 -0 0</pose>
        <mass>23.535</mass>
        <inertia>
          <ixx>11.4018</ixx>
          <ixy>-0.018938</ixy>
          <ixz>-0.0242516</ixz>
          <iyy>11.5643</iyy>
          <iyz>-0.00532544</iyz>
          <izz>11.4493</izz>
        </inertia>
      </inertial>
      <collision name='base_link_collision'>
        <pose frame=''>0 0 0.177 0 -0 0</pose>
        <geometry>
          <mesh>
            <scale>1 1 1</scale>
            <uri>model://amr_robots_description/meshes/p3at_meshes/chassis.stl</uri>
          </mesh>
        </geometry>
        <surface>
          <contact>
            <ode/>
          </contact>
          <friction>
            <ode/>
          </friction>
        </surface>
      </collision>
      <collision name='base_link_fixed_joint_lump__kinect_collision_collision_1'>
        <pose frame=''>0.227093 0 0.334795 0 0.1 0</pose>
        <geometry>
          <box>
            <size>0.065 0.25 0.082</size>
          </box>
        </geometry>
      </collision>
      <collision name='base_link_fixed_joint_lump__KinectCo_collision_2'>
        <pose frame=''>0.223 0 0.294 0 0.1 0</pose>
        <geometry>
          <box>
            <size>0.265 0.25 0.082</size>
          </box>
        </geometry>
      </collision>
      <collision name='base_link_fixed_joint_lump__p3at_back_left_axle_collision_3'>
        <pose frame=''>-0.134 0.156 0.111 0 -0 0</pose>
        <geometry>
          <mesh>
            <scale>1 1 1</scale>
            <uri>model://amr_robots_description/meshes/p3at_meshes/axle.stl</uri>
          </mesh>
        </geometry>
        <surface>
          <contact>
            <ode/>
          </contact>
          <friction>
            <ode/>
          </friction>
        </surface>
      </collision>
      <collision name='base_link_fixed_joint_lump__p3at_back_left_hub_collision_4'>
        <pose frame=''>-0.134 0.197 0.111 0 -0 0</pose>
        <geometry>
          <mesh>
            <scale>1 1 1</scale>
            <uri>model://amr_robots_description/meshes/p3at_meshes/left_hubcap.stl</uri>
          </mesh>
        </geometry>
        <surface>
          <contact>
            <ode/>
          </contact>
          <friction>
            <ode/>
          </friction>
        </surface>
      </collision>
      <collision name='base_link_fixed_joint_lump__p3at_back_right_axle_collision_5'>
        <pose frame=''>-0.134 -0.156 0.111 0 -0 0</pose>
        <geometry>
          <mesh>
            <scale>1 1 1</scale>
            <uri>model://amr_robots_description/meshes/p3at_meshes/axle.stl</uri>
          </mesh>
        </geometry>
        <surface>
          <contact>
            <ode/>
          </contact>
          <friction>
            <ode/>
          </friction>
        </surface>
      </collision>
      <collision name='base_link_fixed_joint_lump__p3at_back_right_hub_collision_6'>
        <pose frame=''>-0.134 -0.197 0.111 0 -0 0</pose>
        <geometry>
          <mesh>
            <scale>1 1 1</scale>
            <uri>model://amr_robots_description/meshes/p3at_meshes/right_hubcap.stl</uri>
          </mesh>
        </geometry>
        <surface>
          <contact>
            <ode/>
          </contact>
          <friction>
            <ode/>
          </friction>
        </surface>
      </collision>
      <visual name='base_link_visual'>
        <pose frame=''>0 0 0.177 0 -0 0</pose>
        <geometry>
          <mesh>
            <scale>1 1 1</scale>
            <uri>model://amr_robots_description/meshes/p3at_meshes/chassis.stl</uri>
          </mesh>
        </geometry>
        <material>
          <script>
            <name>Gazebo/Red</name>
            <uri>file://media/materials/scripts/gazebo.material</uri>
          </script>
        </material>
      </visual>
      <visual name='base_link_fixed_joint_lump__back_sonar_visual_1'>
        <pose frame=''>-0.187 0 0.247 0 -0 0</pose>
        <geometry>
          <mesh>
            <scale>1 1 1</scale>
            <uri>model://amr_robots_description/meshes/p3at_meshes/back_sonar.stl</uri>
          </mesh>
        </geometry>
        <material>
          <script>
            <name>Gazebo/Yellow</name>
            <uri>file://media/materials/scripts/gazebo.material</uri>
          </script>
        </material>
      </visual>
      <visual name='base_link_fixed_joint_lump__front_sonar_visual_2'>
        <pose frame=''>0.193 0 0.25 0 -0 0</pose>
        <geometry>
          <mesh>
            <scale>1 1 1</scale>
            <uri>model://amr_robots_description/meshes/p3at_meshes/front_sonar.stl</uri>
          </mesh>
        </geometry>
        <material>
          <script>
            <name>Gazebo/Yellow</name>
            <uri>file://media/materials/scripts/gazebo.material</uri>
          </script>
        </material>
      </visual>
      <visual name='base_link_fixed_joint_lump__p3at_front_left_axle_visual_3'>
        <pose frame=''>0.135 0.156 0.111 0 -0 0</pose>
        <geometry>
          <mesh>
            <scale>1 1 1</scale>
            <uri>model://amr_robots_description/meshes/p3at_meshes/axle.stl</uri>
          </mesh>
        </geometry>
        <material>
          <script>
            <name>Gazebo/Grey</name>
            <uri>file://media/materials/scripts/gazebo.material</uri>
          </script>
        </material>
      </visual>
      <visual name='base_link_fixed_joint_lump__p3at_front_left_hub_visual_4'>
        <pose frame=''>0.135 0.197 0.111 0 -0 0</pose>
        <geometry>
          <mesh>
            <scale>1 1 1</scale>
            <uri>model://amr_robots_description/meshes/p3at_meshes/left_hubcap.stl</uri>
          </mesh>
        </geometry>
        <material>
          <script>
            <name>Gazebo/Yellow</name>
            <uri>file://media/materials/scripts/gazebo.material</uri>
          </script>
        </material>
      </visual>
      <visual name='base_link_fixed_joint_lump__p3at_front_right_axle_visual_5'>
        <pose frame=''>0.135 -0.156 0.111 0 -0 0</pose>
        <geometry>
          <mesh>
            <scale>1 1 1</scale>
            <uri>model://amr_robots_description/meshes/p3at_meshes/axle.stl</uri>
          </mesh>
        </geometry>
        <material>
          <script>
            <name>Gazebo/Grey</name>
            <uri>file://media/materials/scripts/gazebo.material</uri>
          </script>
        </material>
      </visual>
      <visual name='base_link_fixed_joint_lump__p3at_front_right_hub_visual_6'>
        <pose frame=''>0.135 -0.197 0.111 0 -0 0</pose>
        <geometry>
          <mesh>
            <scale>1 1 1</scale>
            <uri>model://amr_robots_description/meshes/p3at_meshes/right_hubcap.stl</uri>
          </mesh>
        </geometry>
        <material>
          <script>
            <name>Gazebo/Yellow</name>
            <uri>file://media/materials/scripts/gazebo.material</uri>
          </script>
        </material>
      </visual>
      <visual name='base_link_fixed_joint_lump__top_plate_visual_7'>
        <pose frame=''>0.003 0 0.274 0 -0 0</pose>
        <geometry>
          <mesh>
            <scale>1 1 1</scale>
            <uri>model://amr_robots_description/meshes/p3at_meshes/top.stl</uri>
          </mesh>
        </geometry>
        <material>
          <script>
            <name>Gazebo/Black</name>
            <uri>file://media/materials/scripts/gazebo.material</uri>
          </script>
        </material>
      </visual>
      <visual name='base_link_fixed_joint_lump__kinect_link_visual_8'>
        <pose frame=''>0.223 0 0.294 0 0.1 0</pose>
        <geometry>
          <mesh>
            <scale>1 1 1</scale>
            <uri>model://multi_kinect_description/meshes/sensor/visual/COLLADA/kinectv2.stl</uri>
          </mesh>
        </geometry>
        <material>
          <script>
            <name>Gazebo/Black</name>
            <uri>file://media/materials/scripts/gazebo.material</uri>
          </script>
        </material>
      </visual>
      <visual name='base_link_fixed_joint_lump__p3at_back_left_axle_visual_9'>
        <pose frame=''>-0.134 0.156 0.111 0 -0 0</pose>
        <geometry>
          <mesh>
            <scale>1 1 1</scale>
            <uri>model://amr_robots_description/meshes/p3at_meshes/axle.stl</uri>
          </mesh>
        </geometry>
        <material>
          <script>
            <name>Gazebo/Grey</name>
            <uri>file://media/materials/scripts/gazebo.material</uri>
          </script>
        </material>
      </visual>
      <visual name='base_link_fixed_joint_lump__p3at_back_left_hub_visual_10'>
        <pose frame=''>-0.134 0.197 0.111 0 -0 0</pose>
        <geometry>
          <mesh>
            <scale>1 1 1</scale>
            <uri>model://amr_robots_description/meshes/p3at_meshes/left_hubcap.stl</uri>
          </mesh>
        </geometry>
        <material>
          <script>
            <name>Gazebo/Yellow</name>
            <uri>file://media/materials/scripts/gazebo.material</uri>
          </script>
        </material>
      </visual>
      <visual name='base_link_fixed_joint_lump__p3at_back_right_axle_visual_11'>
        <pose frame=''>-0.134 -0.156 0.111 0 -0 0</pose>
        <geometry>
          <mesh>
            <scale>1 1 1</scale>
            <uri>model://amr_robots_description/meshes/p3at_meshes/axle.stl</uri>
          </mesh>
        </geometry>
        <material>
          <script>
            <name>Gazebo/Grey</name>
            <uri>file://media/materials/scripts/gazebo.material</uri>
          </script>
        </material>
      </visual>
      <visual name='base_link_fixed_joint_lump__p3at_back_right_hub_visual_12'>
        <pose frame=''>-0.134 -0.197 0.111 0 -0 0</pose>
        <geometry>
          <mesh>
            <scale>1 1 1</scale>
            <uri>model://amr_robots_description/meshes/p3at_meshes/right_hubcap.stl</uri>
          </mesh>
        </geometry>
        <material>
          <script>
            <name>Gazebo/Yellow</name>
            <uri>file://media/materials/scripts/gazebo.material</uri>
          </script>
        </material>
      </visual>
      <velocity_decay/>
      <velocity_decay/>
      <velocity_decay/>
      <velocity_decay/>
      <velocity_decay/>
      <velocity_decay/>
      <velocity_decay/>
      <velocity_decay/>
      <velocity_decay/>
      <sensor name='contact_sensor' type='contact'>
        <contact>
          <collision>base_link_fixed_joint_lump__KinectCo_collision_2</collision>
          <topic>collision_indicator</topic>
        </contact>
        <plugin name='Kinect_gazebo_ros_bumper_controller' filename='libgazebo_ros_bumper.so'>
          <alwaysOn>true</alwaysOn>
          <update_rate>10000.0</update_rate>
          <bumperTopicName>collision_indicator</bumperTopicName>
          <frameName>world</frameName>
        </plugin>
        <pose frame=''>0.223 0 0.294 0 0.1 0</pose>
      </sensor>
      <sensor name='P3AT/kinect2' type='depth'>
        <always_on>1</always_on>
        <update_rate>30</update_rate>
        <camera name='__default__'>
          <horizontal_fov>1.46782</horizontal_fov>
          <image>
            <format>B8G8R8</format>
            <width>512</width>
            <height>424</height>
          </image>
          <clip>
            <near>0.05</near>
            <far>4.5</far>
          </clip>
          <noise>
            <type>gaussian</type>
            <mean>0</mean>
            <stddev>0.005</stddev>
          </noise>
        </camera>
        <plugin name='kinect2_camera_controller' filename='libgazebo_ros_openni_kinect.so'>
          <cameraName>P3AT/kinect2/hd</cameraName>
          <alwaysOn>true</alwaysOn>
          <updateRate>30</updateRate>
          <imageTopicName>image_color</imageTopicName>
          <depthImageTopicName>image_depth</depthImageTopicName>
          <pointCloudTopicName>points</pointCloudTopicName>
          <cameraInfoTopicName>camera_info</cameraInfoTopicName>
          <depthImageCameraInfoTopicName>camera_info</depthImageCameraInfoTopicName>
          <frameName>P3AT/kinect2_rgb_optical_frame</frameName>
          <baseline>0.1</baseline>
          <distortion_k1>0.0</distortion_k1>
          <distortion_k2>0.0</distortion_k2>
          <distortion_k3>0.0</distortion_k3>
          <distortion_t1>0.0</distortion_t1>
          <distortion_t2>0.0</distortion_t2>
          <pointCloudCutoff>0.05</pointCloudCutoff>
          <pointCloudCutoffMax>4.5</pointCloudCutoffMax>
        </plugin>
        <pose frame=''>0.223 0 0.294 0 0.1 0</pose>
      </sensor>
      <velocity_decay/>
      <velocity_decay/>
      <velocity_decay/>
      <gravity>1</gravity>
      <velocity_decay/>
      <self_collide>0</self_collide>
    </link>
    <link name='p3at_front_left_wheel'>
      <pose frame=''>0.135 0.197 0.111 0 -0 0</pose>
      <inertial>
        <pose frame=''>0 0 0 0 -0 0</pose>
        <mass>1.2</mass>
        <inertia>
          <ixx>0.0124118</ixx>
          <ixy>0</ixy>
          <ixz>0</ixz>
          <iyy>0.0152182</iyy>
          <iyz>0</iyz>
          <izz>0.011764</izz>
        </inertia>
      </inertial>
      <collision name='p3at_front_left_wheel_collision'>
        <pose frame=''>0 0 0 -1.5708 0 0</pose>
        <geometry>
          <cylinder>
            <length>0.075</length>
            <radius>0.111</radius>
          </cylinder>
        </geometry>
        <surface>
          <contact>
            <ode>
              <kp>1e+06</kp>
              <kd>100</kd>
              <max_vel>1</max_vel>
              <min_depth>0</min_depth>
            </ode>
          </contact>
          <friction>
            <ode>
              <mu>1</mu>
              <mu2>1</mu2>
            </ode>
          </friction>
        </surface>
      </collision>
      <visual name='p3at_front_left_wheel_visual'>
        <pose frame=''>0 0 0 0 -0 0</pose>
        <geometry>
          <mesh>
            <scale>1 1 1</scale>
            <uri>model://amr_robots_description/meshes/p3at_meshes/wheel.stl</uri>
          </mesh>
        </geometry>
        <material>
          <script>
            <name>Gazebo/Black</name>
            <uri>file://media/materials/scripts/gazebo.material</uri>
          </script>
        </material>
      </visual>
      <velocity_decay/>
      <gravity>1</gravity>
      <velocity_decay/>
      <self_collide>0</self_collide>
    </link>
    <joint name='p3at_front_left_wheel_joint' type='revolute'>
      <child>p3at_front_left_wheel</child>
      <parent>base_link</parent>
      <axis>
        <xyz>0 1 0</xyz>
        <limit>
          <lower>-1e+16</lower>
          <upper>1e+16</upper>
        </limit>
        <dynamics>
          <spring_reference>0</spring_reference>
          <spring_stiffness>0</spring_stiffness>
        </dynamics>
        <use_parent_model_frame>1</use_parent_model_frame>
      </axis>
    </joint>
    <link name='p3at_front_right_wheel'>
      <pose frame=''>0.135 -0.197 0.111 0 -0 0</pose>
      <inertial>
        <pose frame=''>0 0 0 0 -0 0</pose>
        <mass>1.2</mass>
        <inertia>
          <ixx>0.0124118</ixx>
          <ixy>0</ixy>
          <ixz>0</ixz>
          <iyy>0.0152182</iyy>
          <iyz>0</iyz>
          <izz>0.011764</izz>
        </inertia>
      </inertial>
      <collision name='p3at_front_right_wheel_collision'>
        <pose frame=''>0 0 0 -1.5708 0 0</pose>
        <geometry>
          <cylinder>
            <length>0.075</length>
            <radius>0.111</radius>
          </cylinder>
        </geometry>
        <surface>
          <contact>
            <ode>
              <kp>1e+06</kp>
              <kd>100</kd>
              <max_vel>1</max_vel>
              <min_depth>0</min_depth>
            </ode>
          </contact>
          <friction>
            <ode>
              <mu>1</mu>
              <mu2>1</mu2>
            </ode>
          </friction>
        </surface>
      </collision>
      <visual name='p3at_front_right_wheel_visual'>
        <pose frame=''>0 0 0 0 -0 0</pose>
        <geometry>
          <mesh>
            <scale>1 1 1</scale>
            <uri>model://amr_robots_description/meshes/p3at_meshes/wheel.stl</uri>
          </mesh>
        </geometry>
        <material>
          <script>
            <name>Gazebo/Black</name>
            <uri>file://media/materials/scripts/gazebo.material</uri>
          </script>
        </material>
      </visual>
      <velocity_decay/>
      <gravity>1</gravity>
      <velocity_decay/>
      <self_collide>0</self_collide>
    </link>
    <joint name='p3at_front_right_wheel_joint' type='revolute'>
      <child>p3at_front_right_wheel</child>
      <parent>base_link</parent>
      <axis>
        <xyz>0 1 0</xyz>
        <limit>
          <lower>-1e+16</lower>
          <upper>1e+16</upper>
        </limit>
        <dynamics>
          <spring_reference>0</spring_reference>
          <spring_stiffness>0</spring_stiffness>
        </dynamics>
        <use_parent_model_frame>1</use_parent_model_frame>
      </axis>
    </joint>
    <link name='p3at_back_left_wheel'>
      <pose frame=''>-0.134 0.197 0.111 0 -0 0</pose>
      <inertial>
        <pose frame=''>0 0 0 0 -0 0</pose>
        <mass>1.2</mass>
        <inertia>
          <ixx>0.0124118</ixx>
          <ixy>0</ixy>
          <ixz>0</ixz>
          <iyy>0.0152182</iyy>
          <iyz>0</iyz>
          <izz>0.011764</izz>
        </inertia>
      </inertial>
      <collision name='p3at_back_left_wheel_collision'>
        <pose frame=''>0 0 0 -1.5708 0 0</pose>
        <geometry>
          <cylinder>
            <length>0.075</length>
            <radius>0.111</radius>
          </cylinder>
        </geometry>
        <surface>
          <contact>
            <ode>
              <kp>1e+06</kp>
              <kd>100</kd>
              <max_vel>1</max_vel>
              <min_depth>0</min_depth>
            </ode>
          </contact>
          <friction>
            <ode>
              <mu>1</mu>
              <mu2>1</mu2>
            </ode>
          </friction>
        </surface>
      </collision>
      <visual name='p3at_back_left_wheel_visual'>
        <pose frame=''>0 0 0 0 -0 0</pose>
        <geometry>
          <mesh>
            <scale>1 1 1</scale>
            <uri>model://amr_robots_description/meshes/p3at_meshes/wheel.stl</uri>
          </mesh>
        </geometry>
        <material>
          <script>
            <name>Gazebo/Black</name>
            <uri>file://media/materials/scripts/gazebo.material</uri>
          </script>
        </material>
      </visual>
      <velocity_decay/>
      <gravity>1</gravity>
      <velocity_decay/>
      <self_collide>0</self_collide>
    </link>
    <joint name='p3at_back_left_wheel_joint' type='revolute'>
      <child>p3at_back_left_wheel</child>
      <parent>base_link</parent>
      <axis>
        <xyz>0 1 0</xyz>
        <limit>
          <lower>-1e+16</lower>
          <upper>1e+16</upper>
        </limit>
        <dynamics>
          <spring_reference>0</spring_reference>
          <spring_stiffness>0</spring_stiffness>
        </dynamics>
        <use_parent_model_frame>1</use_parent_model_frame>
      </axis>
    </joint>
    <link name='p3at_back_right_wheel'>
      <pose frame=''>-0.134 -0.197 0.111 0 -0 0</pose>
      <inertial>
        <pose frame=''>0 0 0 0 -0 0</pose>
        <mass>1.2</mass>
        <inertia>
          <ixx>0.0124118</ixx>
          <ixy>0</ixy>
          <ixz>0</ixz>
          <iyy>0.0152182</iyy>
          <iyz>0</iyz>
          <izz>0.011764</izz>
        </inertia>
      </inertial>
      <collision name='p3at_back_right_wheel_collision'>
        <pose frame=''>0 0 0 -1.5708 0 0</pose>
        <geometry>
          <cylinder>
            <length>0.075</length>
            <radius>0.111</radius>
          </cylinder>
        </geometry>
        <surface>
          <contact>
            <ode>
              <kp>1e+06</kp>
              <kd>100</kd>
              <max_vel>1</max_vel>
              <min_depth>0</min_depth>
            </ode>
          </contact>
          <friction>
            <ode>
              <mu>1</mu>
              <mu2>1</mu2>
            </ode>
          </friction>
        </surface>
      </collision>
      <visual name='p3at_back_right_wheel_visual'>
        <pose frame=''>0 0 0 0 -0 0</pose>
        <geometry>
          <mesh>
            <scale>1 1 1</scale>
            <uri>model://amr_robots_description/meshes/p3at_meshes/wheel.stl</uri>
          </mesh>
        </geometry>
        <material>
          <script>
            <name>Gazebo/Black</name>
            <uri>file://media/materials/scripts/gazebo.material</uri>
          </script>
        </material>
      </visual>
      <velocity_decay/>
      <gravity>1</gravity>
      <velocity_decay/>
      <self_collide>0</self_collide>
    </link>
    <joint name='p3at_back_right_wheel_joint' type='revolute'>
      <child>p3at_back_right_wheel</child>
      <parent>base_link</parent>
      <axis>
        <xyz>0 1 0</xyz>
        <limit>
          <lower>-1e+16</lower>
          <upper>1e+16</upper>
        </limit>
        <dynamics>
          <spring_reference>0</spring_reference>
          <spring_stiffness>0</spring_stiffness>
        </dynamics>
        <use_parent_model_frame>1</use_parent_model_frame>
      </axis>
    </joint>
    <static>0</static>
    <plugin name='skid_steer_drive_controller' filename='libgazebo_ros_skid_steer_drive.so'>
      <updateRate>100.0</updateRate>
      <robotNamespace>sim_p3at</robotNamespace>
      <leftFrontJoint>p3at_front_left_wheel_joint</leftFrontJoint>
      <rightFrontJoint>p3at_front_right_wheel_joint</rightFrontJoint>
      <leftRearJoint>p3at_back_left_wheel_joint</leftRearJoint>
      <rightRearJoint>p3at_back_right_wheel_joint</rightRearJoint>
      <wheelSeparation>0.4</wheelSeparation>
      <wheelDiameter>0.215</wheelDiameter>
      <robotBaseFrame>base_link</robotBaseFrame>
      <MaxForce>5.0</MaxForce>
      <torque>200</torque>
      <commandTopic>cmd_vel</commandTopic>
      <odometryTopic>odom</odometryTopic>
      <odometryFrame>odom</odometryFrame>
      <broadcastTF>1</broadcastTF>
    </plugin>
  </model>
</sdf>
